Workbook

Sheet Customers_0
A1: Kundennummer | B1: Namen_mit_oder_ohne_Titel_-_Eigennamen_-_Chaotisch | C1: Kundenstatus_1 | D1: Kundenstatus_auch_1 | E1: Hilfsspalte
A2: 20015 | B2: Autohaus Matthias Grawe | E2: =IF(COUNTIF($A:$A,A2)>1,"DOPPELT","OK") -> OK
A3: 20048 | B3: Christel Kügler, Siebeldingen | E3: =IF(COUNTIF($A:$A,A3)>1,"DOPPELT","OK") -> OK
A4: 20201 | B4: Dr. Schurig, Hauenstein | E4: =IF(COUNTIF($A:$A,A4)>1,"DOPPELT","OK") -> OK
A5: 20203 | B5: Dr. Bickel, Pforzheim | E5: =IF(COUNTIF($A:$A,A5)>1,"DOPPELT","OK") -> OK
A6: 20204 | B6: AsA Consulting | E6: =IF(COUNTIF($A:$A,A6)>1,"DOPPELT","OK") -> OK
A7: 20205 | B7: AsA AG | E7: =IF(COUNTIF($A:$A,A7)>1,"DOPPELT","OK") -> OK
A8: 20228 | B8: Dr. Thumulka, KA | E8: =IF(COUNTIF($A:$A,A8)>1,"DOPPELT","OK") -> OK
A9: 20231 | B9: Trimedic, KA | E9: =IF(COUNTIF($A:$A,A9)>1,"DOPPELT","OK") -> OK
A10: 20258 | B10: Dr. Hunting, Zweibrücken | E10: =IF(COUNTIF($A:$A,A10)>1,"DOPPELT","OK") -> OK
A11: 20266 | B11: Dr. A. Dinkler-Evers, Rottenb. | D11: Rente | E11: =IF(COUNTIF($A:$A,A11)>1,"DOPPELT","OK") -> OK
A12: 20269 | B12: Dres. Schmidt/ Riethmüller, RT | D12: gekündigt | E12: =IF(COUNTIF($A:$A,A12)>1,"DOPPELT","OK") -> OK
A13: 20272 | B13: Dr. Kreisel, RT | D13: gekündigt | E13: =IF(COUNTIF($A:$A,A13)>1,"DOPPELT","OK") -> OK
A14: 20276 | B14: Dr Falkenstein, NW | E14: =IF(COUNTIF($A:$A,A14)>1,"DOPPELT","OK") -> OK
A15: 20292 | B15: Dres. Krause, RT | E15: =IF(COUNTIF($A:$A,A15)>1,"DOPPELT","OK") -> OK
A16: 20295 | B16: Dr. Kath, BAD | D16: Rente | E16: =IF(COUNTIF($A:$A,A16)>1,"DOPPELT","OK") -> OK
A17: 20298 | B17: Dr.Bakhtari, LD | D17: gekündigt | E17: =IF(COUNTIF($A:$A,A17)>1,"DOPPELT","OK") -> OK
A18: 20308 | B18: Dr. Kapp, Aalen | D18: gekündigt | E18: =IF(COUNTIF($A:$A,A18)>1,"DOPPELT","OK") -> OK
A19: 20311 | B19: Dr. H. Mahler,Schw.Gmünd | E19: =IF(COUNTIF($A:$A,A19)>1,"DOPPELT","OK") -> OK
A20: 20312 | B20: Dr. Bretschneider, Remels | E20: =IF(COUNTIF($A:$A,A20)>1,"DOPPELT","OK") -> OK
A21: 20316 | B21: Dr. Lindenthal, Hollen | E21: =IF(COUNTIF($A:$A,A21)>1,"DOPPELT","OK") -> OK
A22: 20317 | B22: Dr. Besuden, Leer | E22: =IF(COUNTIF($A:$A,A22)>1,"DOPPELT","OK") -> OK
A23: 20318 | B23: Ralf Zimmermann, Wiesmoor | E23: =IF(COUNTIF($A:$A,A23)>1,"DOPPELT","OK") -> OK
A24: 20319 | B24: Dr. Brinkmann, Moormerl.+W | E24: =IF(COUNTIF($A:$A,A24)>1,"DOPPELT","OK") -> OK
A25: 20320 | B25: Rühle-Klingenstein, Uplengen | D25: gekündigt | E25: =IF(COUNTIF($A:$A,A25)>1,"DOPPELT","OK") -> OK
A26: 20321 | B26: Dr.M. Riegel, Remels | E26: =IF(COUNTIF($A:$A,A26)>1,"DOPPELT","OK") -> OK
A27: 20325 | B27: Dres.Hahn/Gaens, Metzingen | E27: =IF(COUNTIF($A:$A,A27)>1,"DOPPELT","OK") -> OK
A28: 20327 | B28: Dr. Bihlmaier, Römerstein | E28: =IF(COUNTIF($A:$A,A28)>1,"DOPPELT","OK") -> OK
A29: 20331 | B29: Dr. Zirnstein, Langgöns | E29: =IF(COUNTIF($A:$A,A29)>1,"DOPPELT","OK") -> OK
A30: 20333 | B30: Dr. Sayegh, Dissen | D30: Rente | E30: =IF(COUNTIF($A:$A,A30)>1,"DOPPELT","OK") -> OK
A31: 20335 | B31: Dr. Bruder, Lilienthal | D31: gekündigt | E31: =IF(COUNTIF($A:$A,A31)>1,"DOPPELT","OK") -> OK
A32: 20337 | B32: Dr.Winter , HB-Walle | E32: =IF(COUNTIF($A:$A,A32)>1,"DOPPELT","OK") -> OK
A33: 20338 | B33: F.Heidorn, Bösel | E33: =IF(COUNTIF($A:$A,A33)>1,"DOPPELT","OK") -> OK
A34: 20341 | B34: Dr. Reiff, Metzingen | D34: Rente | E34: =IF(COUNTIF($A:$A,A34)>1,"DOPPELT","OK") -> OK
A35: 20342 | B35: Dr. Röhm, Reutlingen | E35: =IF(COUNTIF($A:$A,A35)>1,"DOPPELT","OK") -> OK
A36: 20345 | B36: Dr.G.Müller, Niederzier | E36: =IF(COUNTIF($A:$A,A36)>1,"DOPPELT","OK") -> OK
A37: 20349 | B37: Dr. Hupfauf/Matt,Westerstetten | D37: Nachfolger | E37: =IF(COUNTIF($A:$A,A37)>1,"DOPPELT","OK") -> OK
A38: 20352 | B38: Dres.Breitinger/ Stroebele, Rotte. | E38: =IF(COUNTIF($A:$A,A38)>1,"DOPPELT","OK") -> OK
A39: 20354 | B39: HNO Schicke, Maxdorf | E39: =IF(COUNTIF($A:$A,A39)>1,"DOPPELT","OK") -> OK
A40: 20357 | B40: Dres. Bauer, Barnstorf | D40: Nachfolger | E40: =IF(COUNTIF($A:$A,A40)>1,"DOPPELT","OK") -> OK
...

Sheet Customers
A1: customerNumber | B1: uniqueName | C1: title | D1: firstName | E1: lastName | F1: street | G1: houseNumber | H1: zipCode | I1: city | J1: state | K1: country | L1: phoneGeneral | M1: mobileGeneral | N1: status | O1: checkName
A2: =Customers_0!A2 -> 20015 | B2: =IFERROR(MID(Customers_0!B2,1,SEARCH(",",Customers_0!B2)-1),Customers_0!B2) -> Autohaus Matthias Grawe | C2: =IFERROR( IF(OR( LEFT(B2,3)="Dr.", LEFT(B2,2)="Dr", LEFT(B2,4)="Dres", LEFT(B2,5)="Dres.", LEFT(B2,4)="Prof", LEFT(B2,5)="Prof.", LEFT(B2,3)="PD ", LEFT(B2,7)="Priv.-D" ), LEFT(B2,SEARCH(" ",B2)-1), "" ), "") | D2: =IFERROR( IF(C2="", "", IF(ISNUMBER(SEARCH(".",MID(B2,LEN(C2)+2,3))), MID(B2,LEN(C2)+2,2), "" ) ), "") | E2: =IFERROR( TRIM( IF(C2="", IF(ISNUMBER(SEARCH(",",B2)), LEFT(B2,SEARCH(",",B2)-1), B2), IF(D2="", TRIM(MID(B2, LEN(C2)+2, 999)), TRIM(MID(B2, LEN(C2&" "&D2)+2, 999)) ) ) ), "" ) -> Autohaus Matthias Grawe | N2: =IF(OR(ISNUMBER(SEARCH("weg",[1]Tabelle1!C2&Customers_0!D2)), ISNUMBER(SEARCH("gekündigt",Customers_0!C2&Customers_0!D2)), ISNUMBER(SEARCH("rente",LOWER(Customers_0!C2&Customers_0!D2)))), "INACTIVE", "ACTIVE") -> ACTIVE | O2: =IF(OR( ISERROR(D2), ISERROR(E2), ISNUMBER(SEARCH("/",E2)), ISNUMBER(SEARCH("-",E2)) ),"PRÜFEN","OK") -> OK
A3: =Customers_0!A3 -> 20048 | B3: =IFERROR(MID(Customers_0!B3,1,SEARCH(",",Customers_0!B3)-1),Customers_0!B3) -> Christel Kügler | C3: =IFERROR( IF(OR( LEFT(B3,3)="Dr.", LEFT(B3,2)="Dr", LEFT(B3,4)="Dres", LEFT(B3,5)="Dres.", LEFT(B3,4)="Prof", LEFT(B3,5)="Prof.", LEFT(B3,3)="PD ", LEFT(B3,7)="Priv.-D" ), LEFT(B3,SEARCH(" ",B3)-1), "" ), "") | D3: =IFERROR( IF(C3="", "", IF(ISNUMBER(SEARCH(".",MID(B3,LEN(C3)+2,3))), MID(B3,LEN(C3)+2,2), "" ) ), "") | E3: =IFERROR( TRIM( IF(C3="", IF(ISNUMBER(SEARCH(",",B3)), LEFT(B3,SEARCH(",",B3)-1), B3), IF(D3="", TRIM(MID(B3, LEN(C3)+2, 999)), TRIM(MID(B3, LEN(C3&" "&D3)+2, 999)) ) ) ), "" ) -> Christel Kügler | N3: =IF(OR(ISNUMBER(SEARCH("weg",[1]Tabelle1!C3&Customers_0!D3)), ISNUMBER(SEARCH("gekündigt",Customers_0!C3&Customers_0!D3)), ISNUMBER(SEARCH("rente",LOWER(Customers_0!C3&Customers_0!D3)))), "INACTIVE", "ACTIVE") -> ACTIVE | O3: =IF(OR( ISERROR(D3), ISERROR(E3), ISNUMBER(SEARCH("/",E3)), ISNUMBER(SEARCH("-",E3)) ),"PRÜFEN","OK") -> OK
A4: =Customers_0!A4 -> 20201 | B4: =IFERROR(MID(Customers_0!B4,1,SEARCH(",",Customers_0!B4)-1),Customers_0!B4) -> Dr. Schurig | C4: =IFERROR( IF(OR( LEFT(B4,3)="Dr.", LEFT(B4,2)="Dr", LEFT(B4,4)="Dres", LEFT(B4,5)="Dres.", LEFT(B4,4)="Prof", LEFT(B4,5)="Prof.", LEFT(B4,3)="PD ", LEFT(B4,7)="Priv.-D" ), LEFT(B4,SEARCH(" ",B4)-1), "" ), "") -> Dr. | D4: =IFERROR( IF(C4="", "", IF(ISNUMBER(SEARCH(".",MID(B4,LEN(C4)+2,3))), MID(B4,LEN(C4)+2,2), "" ) ), "") | E4: =IFERROR( TRIM( IF(C4="", IF(ISNUMBER(SEARCH(",",B4)), LEFT(B4,SEARCH(",",B4)-1), B4), IF(D4="", TRIM(MID(B4, LEN(C4)+2, 999)), TRIM(MID(B4, LEN(C4&" "&D4)+2, 999)) ) ) ), "" ) -> Schurig | N4: =IF(OR(ISNUMBER(SEARCH("weg",[1]Tabelle1!C4&Customers_0!D4)), ISNUMBER(SEARCH("gekündigt",Customers_0!C4&Customers_0!D4)), ISNUMBER(SEARCH("rente",LOWER(Customers_0!C4&Customers_0!D4)))), "INACTIVE", "ACTIVE") -> ACTIVE | O4: =IF(OR( ISERROR(D4), ISERROR(E4), ISNUMBER(SEARCH("/",E4)), ISNUMBER(SEARCH("-",E4)) ),"PRÜFEN","OK") -> OK
A5: =Customers_0!A5 -> 20203 | B5: =IFERROR(MID(Customers_0!B5,1,SEARCH(",",Customers_0!B5)-1),Customers_0!B5) -> Dr. Bickel | C5: =IFERROR( IF(OR( LEFT(B5,3)="Dr.", LEFT(B5,2)="Dr", LEFT(B5,4)="Dres", LEFT(B5,5)="Dres.", LEFT(B5,4)="Prof", LEFT(B5,5)="Prof.", LEFT(B5,3)="PD ", LEFT(B5,7)="Priv.-D" ), LEFT(B5,SEARCH(" ",B5)-1), "" ), "") -> Dr. | D5: =IFERROR( IF(C5="", "", IF(ISNUMBER(SEARCH(".",MID(B5,LEN(C5)+2,3))), MID(B5,LEN(C5)+2,2), "" ) ), "") | E5: =IFERROR( TRIM( IF(C5="", IF(ISNUMBER(SEARCH(",",B5)), LEFT(B5,SEARCH(",",B5)-1), B5), IF(D5="", TRIM(MID(B5, LEN(C5)+2, 999)), TRIM(MID(B5, LEN(C5&" "&D5)+2, 999)) ) ) ), "" ) -> Bickel | N5: =IF(OR(ISNUMBER(SEARCH("weg",[1]Tabelle1!C5&Customers_0!D5)), ISNUMBER(SEARCH("gekündigt",Customers_0!C5&Customers_0!D5)), ISNUMBER(SEARCH("rente",LOWER(Customers_0!C5&Customers_0!D5)))), "INACTIVE", "ACTIVE") -> ACTIVE | O5: =IF(OR( ISERROR(D5), ISERROR(E5), ISNUMBER(SEARCH("/",E5)), ISNUMBER(SEARCH("-",E5)) ),"PRÜFEN","OK") -> OK
A6: =Customers_0!A6 -> 20204 | B6: =IFERROR(MID(Customers_0!B6,1,SEARCH(",",Customers_0!B6)-1),Customers_0!B6) -> AsA Consulting | C6: =IFERROR( IF(OR( LEFT(B6,3)="Dr.", LEFT(B6,2)="Dr", LEFT(B6,4)="Dres", LEFT(B6,5)="Dres.", LEFT(B6,4)="Prof", LEFT(B6,5)="Prof.", LEFT(B6,3)="PD ", LEFT(B6,7)="Priv.-D" ), LEFT(B6,SEARCH(" ",B6)-1), "" ), "") | D6: =IFERROR( IF(C6="", "", IF(ISNUMBER(SEARCH(".",MID(B6,LEN(C6)+2,3))), MID(B6,LEN(C6)+2,2), "" ) ), "") | E6: =IFERROR( TRIM( IF(C6="", IF(ISNUMBER(SEARCH(",",B6)), LEFT(B6,SEARCH(",",B6)-1), B6), IF(D6="", TRIM(MID(B6, LEN(C6)+2, 999)), TRIM(MID(B6, LEN(C6&" "&D6)+2, 999)) ) ) ), "" ) -> AsA Consulting | N6: =IF(OR(ISNUMBER(SEARCH("weg",[1]Tabelle1!C6&Customers_0!D6)), ISNUMBER(SEARCH("gekündigt",Customers_0!C6&Customers_0!D6)), ISNUMBER(SEARCH("rente",LOWER(Customers_0!C6&Customers_0!D6)))), "INACTIVE", "ACTIVE") -> ACTIVE | O6: =IF(OR( ISERROR(D6), ISERROR(E6), ISNUMBER(SEARCH("/",E6)), ISNUMBER(SEARCH("-",E6)) ),"PRÜFEN","OK") -> OK
A7: =Customers_0!A7 -> 20205 | B7: =IFERROR(MID(Customers_0!B7,1,SEARCH(",",Customers_0!B7)-1),Customers_0!B7) -> AsA AG | C7: =IFERROR( IF(OR( LEFT(B7,3)="Dr.", LEFT(B7,2)="Dr", LEFT(B7,4)="Dres", LEFT(B7,5)="Dres.", LEFT(B7,4)="Prof", LEFT(B7,5)="Prof.", LEFT(B7,3)="PD ", LEFT(B7,7)="Priv.-D" ), LEFT(B7,SEARCH(" ",B7)-1), "" ), "") | D7: =IFERROR( IF(C7="", "", IF(ISNUMBER(SEARCH(".",MID(B7,LEN(C7)+2,3))), MID(B7,LEN(C7)+2,2), "" ) ), "") | E7: =IFERROR( TRIM( IF(C7="", IF(ISNUMBER(SEARCH(",",B7)), LEFT(B7,SEARCH(",",B7)-1), B7), IF(D7="", TRIM(MID(B7, LEN(C7)+2, 999)), TRIM(MID(B7, LEN(C7&" "&D7)+2, 999)) ) ) ), "" ) -> AsA AG | N7: =IF(OR(ISNUMBER(SEARCH("weg",[1]Tabelle1!C7&Customers_0!D7)), ISNUMBER(SEARCH("gekündigt",Customers_0!C7&Customers_0!D7)), ISNUMBER(SEARCH("rente",LOWER(Customers_0!C7&Customers_0!D7)))), "INACTIVE", "ACTIVE") -> ACTIVE | O7: =IF(OR( ISERROR(D7), ISERROR(E7), ISNUMBER(SEARCH("/",E7)), ISNUMBER(SEARCH("-",E7)) ),"PRÜFEN","OK") -> OK
A8: =Customers_0!A8 -> 20228 | B8: =IFERROR(MID(Customers_0!B8,1,SEARCH(",",Customers_0!B8)-1),Customers_0!B8) -> Dr. Thumulka | C8: =IFERROR( IF(OR( LEFT(B8,3)="Dr.", LEFT(B8,2)="Dr", LEFT(B8,4)="Dres", LEFT(B8,5)="Dres.", LEFT(B8,4)="Prof", LEFT(B8,5)="Prof.", LEFT(B8,3)="PD ", LEFT(B8,7)="Priv.-D" ), LEFT(B8,SEARCH(" ",B8)-1), "" ), "") -> Dr. | D8: =IFERROR( IF(C8="", "", IF(ISNUMBER(SEARCH(".",MID(B8,LEN(C8)+2,3))), MID(B8,LEN(C8)+2,2), "" ) ), "") | E8: =IFERROR( TRIM( IF(C8="", IF(ISNUMBER(SEARCH(",",B8)), LEFT(B8,SEARCH(",",B8)-1), B8), IF(D8="", TRIM(MID(B8, LEN(C8)+2, 999)), TRIM(MID(B8, LEN(C8&" "&D8)+2, 999)) ) ) ), "" ) -> Thumulka | N8: =IF(OR(ISNUMBER(SEARCH("weg",[1]Tabelle1!C8&Customers_0!D8)), ISNUMBER(SEARCH("gekündigt",Customers_0!C8&Customers_0!D8)), ISNUMBER(SEARCH("rente",LOWER(Customers_0!C8&Customers_0!D8)))), "INACTIVE", "ACTIVE") -> ACTIVE | O8: =IF(OR( ISERROR(D8), ISERROR(E8), ISNUMBER(SEARCH("/",E8)), ISNUMBER(SEARCH("-",E8)) ),"PRÜFEN","OK") -> OK
A9: =Customers_0!A9 -> 20231 | B9: =IFERROR(MID(Customers_0!B9,1,SEARCH(",",Customers_0!B9)-1),Customers_0!B9) -> Trimedic | C9: =IFERROR( IF(OR( LEFT(B9,3)="Dr.", LEFT(B9,2)="Dr", LEFT(B9,4)="Dres", LEFT(B9,5)="Dres.", LEFT(B9,4)="Prof", LEFT(B9,5)="Prof.", LEFT(B9,3)="PD ", LEFT(B9,7)="Priv.-D" ), LEFT(B9,SEARCH(" ",B9)-1), "" ), "") | D9: =IFERROR( IF(C9="", "", IF(ISNUMBER(SEARCH(".",MID(B9,LEN(C9)+2,3))), MID(B9,LEN(C9)+2,2), "" ) ), "") | E9: =IFERROR( TRIM( IF(C9="", IF(ISNUMBER(SEARCH(",",B9)), LEFT(B9,SEARCH(",",B9)-1), B9), IF(D9="", TRIM(MID(B9, LEN(C9)+2, 999)), TRIM(MID(B9, LEN(C9&" "&D9)+2, 999)) ) ) ), "" ) -> Trimedic | N9: =IF(OR(ISNUMBER(SEARCH("weg",[1]Tabelle1!C9&Customers_0!D9)), ISNUMBER(SEARCH("gekündigt",Customers_0!C9&Customers_0!D9)), ISNUMBER(SEARCH("rente",LOWER(Customers_0!C9&Customers_0!D9)))), "INACTIVE", "ACTIVE") -> ACTIVE | O9: =IF(OR( ISERROR(D9), ISERROR(E9), ISNUMBER(SEARCH("/",E9)), ISNUMBER(SEARCH("-",E9)) ),"PRÜFEN","OK") -> OK
A10: =Customers_0!A10 -> 20258 | B10: =IFERROR(MID(Customers_0!B10,1,SEARCH(",",Customers_0!B10)-1),Customers_0!B10) -> Dr. Hunting | C10: =IFERROR( IF(OR( LEFT(B10,3)="Dr.", LEFT(B10,2)="Dr", LEFT(B10,4)="Dres", LEFT(B10,5)="Dres.", LEFT(B10,4)="Prof", LEFT(B10,5)="Prof.", LEFT(B10,3)="PD ", LEFT(B10,7)="Priv.-D" ), LEFT(B10,SEARCH(" ",B10)-1), "" ), "") -> Dr. | D10: =IFERROR( IF(C10="", "", IF(ISNUMBER(SEARCH(".",MID(B10,LEN(C10)+2,3))), MID(B10,LEN(C10)+2,2), "" ) ), "") | E10: =IFERROR( TRIM( IF(C10="", IF(ISNUMBER(SEARCH(",",B10)), LEFT(B10,SEARCH(",",B10)-1), B10), IF(D10="", TRIM(MID(B10, LEN(C10)+2, 999)), TRIM(MID(B10, LEN(C10&" "&D10)+2, 999)) ) ) ), "" ) -> Hunting | N10: =IF(OR(ISNUMBER(SEARCH("weg",[1]Tabelle1!C10&Customers_0!D10)), ISNUMBER(SEARCH("gekündigt",Customers_0!C10&Customers_0!D10)), ISNUMBER(SEARCH("rente",LOWER(Customers_0!C10&Customers_0!D10)))), "INACTIVE", "ACTIVE") -> ACTIVE | O10: =IF(OR( ISERROR(D10), ISERROR(E10), ISNUMBER(SEARCH("/",E10)), ISNUMBER(SEARCH("-",E10)) ),"PRÜFEN","OK") -> OK
A11: =Customers_0!A11 -> 20266 | B11: =IFERROR(MID(Customers_0!B11,1,SEARCH(",",Customers_0!B11)-1),Customers_0!B11) -> Dr. A. Dinkler-Evers | C11: =IFERROR( IF(OR( LEFT(B11,3)="Dr.", LEFT(B11,2)="Dr", LEFT(B11,4)="Dres", LEFT(B11,5)="Dres.", LEFT(B11,4)="Prof", LEFT(B11,5)="Prof.", LEFT(B11,3)="PD ", LEFT(B11,7)="Priv.-D" ), LEFT(B11,SEARCH(" ",B11)-1), "" ), "") -> Dr. | D11: =IFERROR( IF(C11="", "", IF(ISNUMBER(SEARCH(".",MID(B11,LEN(C11)+2,3))), MID(B11,LEN(C11)+2,2), "" ) ), "") -> A. | E11: =IFERROR( TRIM( IF(C11="", IF(ISNUMBER(SEARCH(",",B11)), LEFT(B11,SEARCH(",",B11)-1), B11), IF(D11="", TRIM(MID(B11, LEN(C11)+2, 999)), TRIM(MID(B11, LEN(C11&" "&D11)+2, 999)) ) ) ), "" ) -> Dinkler-Evers | N11: =IF(OR(ISNUMBER(SEARCH("weg",[1]Tabelle1!C11&Customers_0!D11)), ISNUMBER(SEARCH("gekündigt",Customers_0!C11&Customers_0!D11)), ISNUMBER(SEARCH("rente",LOWER(Customers_0!C11&Customers_0!D11)))), "INACTIVE", "ACTIVE") -> INACTIVE | O11: =IF(OR( ISERROR(D11), ISERROR(E11), ISNUMBER(SEARCH("/",E11)), ISNUMBER(SEARCH("-",E11)) ),"PRÜFEN","OK") -> PRÜFEN
A12: =Customers_0!A12 -> 20269 | B12: =IFERROR(MID(Customers_0!B12,1,SEARCH(",",Customers_0!B12)-1),Customers_0!B12) -> Dres. Schmidt/ Riethmüller | C12: =IFERROR( IF(OR( LEFT(B12,3)="Dr.", LEFT(B12,2)="Dr", LEFT(B12,4)="Dres", LEFT(B12,5)="Dres.", LEFT(B12,4)="Prof", LEFT(B12,5)="Prof.", LEFT(B12,3)="PD ", LEFT(B12,7)="Priv.-D" ), LEFT(B12,SEARCH(" ",B12)-1), "" ), "") -> Dres. | D12: =IFERROR( IF(C12="", "", IF(ISNUMBER(SEARCH(".",MID(B12,LEN(C12)+2,3))), MID(B12,LEN(C12)+2,2), "" ) ), "") | E12: =IFERROR( TRIM( IF(C12="", IF(ISNUMBER(SEARCH(",",B12)), LEFT(B12,SEARCH(",",B12)-1), B12), IF(D12="", TRIM(MID(B12, LEN(C12)+2, 999)), TRIM(MID(B12, LEN(C12&" "&D12)+2, 999)) ) ) ), "" ) -> Schmidt/ Riethmüller | N12: =IF(OR(ISNUMBER(SEARCH("weg",[1]Tabelle1!C12&Customers_0!D12)), ISNUMBER(SEARCH("gekündigt",Customers_0!C12&Customers_0!D12)), ISNUMBER(SEARCH("rente",LOWER(Customers_0!C12&Customers_0!D12)))), "INACTIVE", "ACTIVE") -> INACTIVE | O12: =IF(OR( ISERROR(D12), ISERROR(E12), ISNUMBER(SEARCH("/",E12)), ISNUMBER(SEARCH("-",E12)) ),"PRÜFEN","OK") -> PRÜFEN
A13: =Customers_0!A13 -> 20272 | B13: =IFERROR(MID(Customers_0!B13,1,SEARCH(",",Customers_0!B13)-1),Customers_0!B13) -> Dr. Kreisel | C13: =IFERROR( IF(OR( LEFT(B13,3)="Dr.", LEFT(B13,2)="Dr", LEFT(B13,4)="Dres", LEFT(B13,5)="Dres.", LEFT(B13,4)="Prof", LEFT(B13,5)="Prof.", LEFT(B13,3)="PD ", LEFT(B13,7)="Priv.-D" ), LEFT(B13,SEARCH(" ",B13)-1), "" ), "") -> Dr. | D13: =IFERROR( IF(C13="", "", IF(ISNUMBER(SEARCH(".",MID(B13,LEN(C13)+2,3))), MID(B13,LEN(C13)+2,2), "" ) ), "") | E13: =IFERROR( TRIM( IF(C13="", IF(ISNUMBER(SEARCH(",",B13)), LEFT(B13,SEARCH(",",B13)-1), B13), IF(D13="", TRIM(MID(B13, LEN(C13)+2, 999)), TRIM(MID(B13, LEN(C13&" "&D13)+2, 999)) ) ) ), "" ) -> Kreisel | N13: =IF(OR(ISNUMBER(SEARCH("weg",[1]Tabelle1!C13&Customers_0!D13)), ISNUMBER(SEARCH("gekündigt",Customers_0!C13&Customers_0!D13)), ISNUMBER(SEARCH("rente",LOWER(Customers_0!C13&Customers_0!D13)))), "INACTIVE", "ACTIVE") -> INACTIVE | O13: =IF(OR( ISERROR(D13), ISERROR(E13), ISNUMBER(SEARCH("/",E13)), ISNUMBER(SEARCH("-",E13)) ),"PRÜFEN","OK") -> OK
... A293: =Customers_0!A293 -> 20849 | B293: =IFERROR(MID(Customers_0!B293,1,SEARCH(",",Customers_0!B293)-1),Customers_0!B293) -> Dr. Nopper | C293: =IFERROR( IF(OR( LEFT(B293,3)="Dr.", LEFT(B293,2)="Dr", LEFT(B293,4)="Dres", LEFT(B293,5)="Dres.", LEFT(B293,4)="Prof", LEFT(B293,5)="Prof.", LEFT(B293,3)="PD ", LEFT(B293,7)="Priv.-D" ), LEFT(B293,SEARCH(" ",B293)-1), "" ), "") -> Dr. | D293: =IFERROR( IF(C293="", "", IF(ISNUMBER(SEARCH(".",MID(B293,LEN(C293)+2,3))), MID(B293,LEN(C293)+2,2), "" ) ), "") | E293: =IFERROR( TRIM( IF(C293="", IF(ISNUMBER(SEARCH(",",B293)), LEFT(B293,SEARCH(",",B293)-1), B293), IF(D293="", TRIM(MID(B293, LEN(C293)+2, 999)), TRIM(MID(B293, LEN(C293&" "&D293)+2, 999)) ) ) ), "" ) -> Nopper | N293: =IF(OR(ISNUMBER(SEARCH("weg",[1]Tabelle1!C293&Customers_0!D293)), ISNUMBER(SEARCH("gekündigt",Customers_0!C293&Customers_0!D293)), ISNUMBER(SEARCH("rente",LOWER(Customers_0!C293&Customers_0!D293)))), "INACTIVE", "ACTIVE") -> ACTIVE | O293: =IF(OR( ISERROR(D293), ISERROR(E293), ISNUMBER(SEARCH("/",E293)), ISNUMBER(SEARCH("-",E293)) ),"PRÜFEN","OK") -> OK
A294: =Customers_0!#REF! -> #REF! | B294: =IFERROR(MID(Customers_0!#REF!,1,SEARCH(",",Customers_0!#REF!)-1),Customers_0!#REF!) -> #REF! | C294: =IFERROR( IF(OR( LEFT(B294,3)="Dr.", LEFT(B294,2)="Dr", LEFT(B294,4)="Dres", LEFT(B294,5)="Dres.", LEFT(B294,4)="Prof", LEFT(B294,5)="Prof.", LEFT(B294,3)="PD ", LEFT(B294,7)="Priv.-D" ), LEFT(B294,SEARCH(" ",B294)-1), "" ), "") | D294: =IFERROR( IF(C294="", "", IF(ISNUMBER(SEARCH(".",MID(B294,LEN(C294)+2,3))), MID(B294,LEN(C294)+2,2), "" ) ), "") | E294: =IFERROR( TRIM( IF(C294="", IF(ISNUMBER(SEARCH(",",B294)), LEFT(B294,SEARCH(",",B294)-1), B294), IF(D294="", TRIM(MID(B294, LEN(C294)+2, 999)), TRIM(MID(B294, LEN(C294&" "&D294)+2, 999)) ) ) ), "" ) | N294: =IF(OR(ISNUMBER(SEARCH("weg",[1]Tabelle1!C294&Customers_0!D294)), ISNUMBER(SEARCH("gekündigt",Customers_0!C294&Customers_0!D294)), ISNUMBER(SEARCH("rente",LOWER(Customers_0!C294&Customers_0!D294)))), "INACTIVE", "ACTIVE") -> INACTIVE | O294: =IF(OR( ISERROR(D294), ISERROR(E294), ISNUMBER(SEARCH("/",E294)), ISNUMBER(SEARCH("-",E294)) ),"PRÜFEN","OK") -> OK
A295: =Customers_0!A295 -> 20852 | B295: =IFERROR(MID(Customers_0!B295,1,SEARCH(",",Customers_0!B295)-1),Customers_0!B295) -> Dres. Graneis/ Schüle-Braun | C295: =IFERROR( IF(OR( LEFT(B295,3)="Dr.", LEFT(B295,2)="Dr", LEFT(B295,4)="Dres", LEFT(B295,5)="Dres.", LEFT(B295,4)="Prof", LEFT(B295,5)="Prof.", LEFT(B295,3)="PD ", LEFT(B295,7)="Priv.-D" ), LEFT(B295,SEARCH(" ",B295)-1), "" ), "") -> Dres. | D295: =IFERROR( IF(C295="", "", IF(ISNUMBER(SEARCH(".",MID(B295,LEN(C295)+2,3))), MID(B295,LEN(C295)+2,2), "" ) ), "") | E295: =IFERROR( TRIM( IF(C295="", IF(ISNUMBER(SEARCH(",",B295)), LEFT(B295,SEARCH(",",B295)-1), B295), IF(D295="", TRIM(MID(B295, LEN(C295)+2, 999)), TRIM(MID(B295, LEN(C295&" "&D295)+2, 999)) ) ) ), "" ) -> Graneis/ Schüle-Braun | N295: =IF(OR(ISNUMBER(SEARCH("weg",[1]Tabelle1!C295&Customers_0!D295)), ISNUMBER(SEARCH("gekündigt",Customers_0!C295&Customers_0!D295)), ISNUMBER(SEARCH("rente",LOWER(Customers_0!C295&Customers_0!D295)))), "INACTIVE", "ACTIVE") -> ACTIVE | O295: =IF(OR( ISERROR(D295), ISERROR(E295), ISNUMBER(SEARCH("/",E295)), ISNUMBER(SEARCH("-",E295)) ),"PRÜFEN","OK") -> PRÜFEN
A296: =Customers_0!A296 -> 20853 | B296: =IFERROR(MID(Customers_0!B296,1,SEARCH(",",Customers_0!B296)-1),Customers_0!B296) -> Dr. Heller | C296: =IFERROR( IF(OR( LEFT(B296,3)="Dr.", LEFT(B296,2)="Dr", LEFT(B296,4)="Dres", LEFT(B296,5)="Dres.", LEFT(B296,4)="Prof", LEFT(B296,5)="Prof.", LEFT(B296,3)="PD ", LEFT(B296,7)="Priv.-D" ), LEFT(B296,SEARCH(" ",B296)-1), "" ), "") -> Dr. | D296: =IFERROR( IF(C296="", "", IF(ISNUMBER(SEARCH(".",MID(B296,LEN(C296)+2,3))), MID(B296,LEN(C296)+2,2), "" ) ), "") | E296: =IFERROR( TRIM( IF(C296="", IF(ISNUMBER(SEARCH(",",B296)), LEFT(B296,SEARCH(",",B296)-1), B296), IF(D296="", TRIM(MID(B296, LEN(C296)+2, 999)), TRIM(MID(B296, LEN(C296&" "&D296)+2, 999)) ) ) ), "" ) -> Heller | N296: =IF(OR(ISNUMBER(SEARCH("weg",[1]Tabelle1!C296&Customers_0!D296)), ISNUMBER(SEARCH("gekündigt",Customers_0!C296&Customers_0!D296)), ISNUMBER(SEARCH("rente",LOWER(Customers_0!C296&Customers_0!D296)))), "INACTIVE", "ACTIVE") -> ACTIVE | O296: =IF(OR( ISERROR(D296), ISERROR(E296), ISNUMBER(SEARCH("/",E296)), ISNUMBER(SEARCH("-",E296)) ),"PRÜFEN","OK") -> OK
A297: =Customers_0!A297 -> 20854 | B297: =IFERROR(MID(Customers_0!B297,1,SEARCH(",",Customers_0!B297)-1),Customers_0!B297) -> Dr. Mao | C297: =IFERROR( IF(OR( LEFT(B297,3)="Dr.", LEFT(B297,2)="Dr", LEFT(B297,4)="Dres", LEFT(B297,5)="Dres.", LEFT(B297,4)="Prof", LEFT(B297,5)="Prof.", LEFT(B297,3)="PD ", LEFT(B297,7)="Priv.-D" ), LEFT(B297,SEARCH(" ",B297)-1), "" ), "") -> Dr. | D297: =IFERROR( IF(C297="", "", IF(ISNUMBER(SEARCH(".",MID(B297,LEN(C297)+2,3))), MID(B297,LEN(C297)+2,2), "" ) ), "") | E297: =IFERROR( TRIM( IF(C297="", IF(ISNUMBER(SEARCH(",",B297)), LEFT(B297,SEARCH(",",B297)-1), B297), IF(D297="", TRIM(MID(B297, LEN(C297)+2, 999)), TRIM(MID(B297, LEN(C297&" "&D297)+2, 999)) ) ) ), "" ) -> Mao | N297: =IF(OR(ISNUMBER(SEARCH("weg",[1]Tabelle1!C297&Customers_0!D297)), ISNUMBER(SEARCH("gekündigt",Customers_0!C297&Customers_0!D297)), ISNUMBER(SEARCH("rente",LOWER(Customers_0!C297&Customers_0!D297)))), "INACTIVE", "ACTIVE") -> ACTIVE | O297: =IF(OR( ISERROR(D297), ISERROR(E297), ISNUMBER(SEARCH("/",E297)), ISNUMBER(SEARCH("-",E297)) ),"PRÜFEN","OK") -> OK
A298: =Customers_0!A298 -> 20855 | B298: =IFERROR(MID(Customers_0!B298,1,SEARCH(",",Customers_0!B298)-1),Customers_0!B298) -> Dr. Schönit | C298: =IFERROR( IF(OR( LEFT(B298,3)="Dr.", LEFT(B298,2)="Dr", LEFT(B298,4)="Dres", LEFT(B298,5)="Dres.", LEFT(B298,4)="Prof", LEFT(B298,5)="Prof.", LEFT(B298,3)="PD ", LEFT(B298,7)="Priv.-D" ), LEFT(B298,SEARCH(" ",B298)-1), "" ), "") -> Dr. | D298: =IFERROR( IF(C298="", "", IF(ISNUMBER(SEARCH(".",MID(B298,LEN(C298)+2,3))), MID(B298,LEN(C298)+2,2), "" ) ), "") | E298: =IFERROR( TRIM( IF(C298="", IF(ISNUMBER(SEARCH(",",B298)), LEFT(B298,SEARCH(",",B298)-1), B298), IF(D298="", TRIM(MID(B298, LEN(C298)+2, 999)), TRIM(MID(B298, LEN(C298&" "&D298)+2, 999)) ) ) ), "" ) -> Schönit | N298: =IF(OR(ISNUMBER(SEARCH("weg",[1]Tabelle1!C298&Customers_0!D298)), ISNUMBER(SEARCH("gekündigt",Customers_0!C298&Customers_0!D298)), ISNUMBER(SEARCH("rente",LOWER(Customers_0!C298&Customers_0!D298)))), "INACTIVE", "ACTIVE") -> ACTIVE | O298: =IF(OR( ISERROR(D298), ISERROR(E298), ISNUMBER(SEARCH("/",E298)), ISNUMBER(SEARCH("-",E298)) ),"PRÜFEN","OK") -> OK
A299: =Customers_0!A299 -> 20856 | B299: =IFERROR(MID(Customers_0!B299,1,SEARCH(",",Customers_0!B299)-1),Customers_0!B299) -> Dr. Boeke | C299: =IFERROR( IF(OR( LEFT(B299,3)="Dr.", LEFT(B299,2)="Dr", LEFT(B299,4)="Dres", LEFT(B299,5)="Dres.", LEFT(B299,4)="Prof", LEFT(B299,5)="Prof.", LEFT(B299,3)="PD ", LEFT(B299,7)="Priv.-D" ), LEFT(B299,SEARCH(" ",B299)-1), "" ), "") -> Dr. | D299: =IFERROR( IF(C299="", "", IF(ISNUMBER(SEARCH(".",MID(B299,LEN(C299)+2,3))), MID(B299,LEN(C299)+2,2), "" ) ), "") | E299: =IFERROR( TRIM( IF(C299="", IF(ISNUMBER(SEARCH(",",B299)), LEFT(B299,SEARCH(",",B299)-1), B299), IF(D299="", TRIM(MID(B299, LEN(C299)+2, 999)), TRIM(MID(B299, LEN(C299&" "&D299)+2, 999)) ) ) ), "" ) -> Boeke | N299: =IF(OR(ISNUMBER(SEARCH("weg",[1]Tabelle1!C299&Customers_0!D299)), ISNUMBER(SEARCH("gekündigt",Customers_0!C299&Customers_0!D299)), ISNUMBER(SEARCH("rente",LOWER(Customers_0!C299&Customers_0!D299)))), "INACTIVE", "ACTIVE") -> ACTIVE | O299: =IF(OR( ISERROR(D299), ISERROR(E299), ISNUMBER(SEARCH("/",E299)), ISNUMBER(SEARCH("-",E299)) ),"PRÜFEN","OK") -> OK
A300: =Customers_0!A300 -> 20857 | B300: =IFERROR(MID(Customers_0!B300,1,SEARCH(",",Customers_0!B300)-1),Customers_0!B300) -> Böhm-Behrendt | C300: =IFERROR( IF(OR( LEFT(B300,3)="Dr.", LEFT(B300,2)="Dr", LEFT(B300,4)="Dres", LEFT(B300,5)="Dres.", LEFT(B300,4)="Prof", LEFT(B300,5)="Prof.", LEFT(B300,3)="PD ", LEFT(B300,7)="Priv.-D" ), LEFT(B300,SEARCH(" ",B300)-1), "" ), "") | D300: =IFERROR( IF(C300="", "", IF(ISNUMBER(SEARCH(".",MID(B300,LEN(C300)+2,3))), MID(B300,LEN(C300)+2,2), "" ) ), "") | E300: =IFERROR( TRIM( IF(C300="", IF(ISNUMBER(SEARCH(",",B300)), LEFT(B300,SEARCH(",",B300)-1), B300), IF(D300="", TRIM(MID(B300, LEN(C300)+2, 999)), TRIM(MID(B300, LEN(C300&" "&D300)+2, 999)) ) ) ), "" ) -> Böhm-Behrendt | N300: =IF(OR(ISNUMBER(SEARCH("weg",[1]Tabelle1!C300&Customers_0!D300)), ISNUMBER(SEARCH("gekündigt",Customers_0!C300&Customers_0!D300)), ISNUMBER(SEARCH("rente",LOWER(Customers_0!C300&Customers_0!D300)))), "INACTIVE", "ACTIVE") -> ACTIVE | O300: =IF(OR( ISERROR(D300), ISERROR(E300), ISNUMBER(SEARCH("/",E300)), ISNUMBER(SEARCH("-",E300)) ),"PRÜFEN","OK") -> PRÜFEN
A301: =Customers_0!A301 -> 20858 | B301: =IFERROR(MID(Customers_0!B301,1,SEARCH(",",Customers_0!B301)-1),Customers_0!B301) -> Drs. Ohlberg/ Wick | C301: =IFERROR( IF(OR( LEFT(B301,3)="Dr.", LEFT(B301,2)="Dr", LEFT(B301,4)="Dres", LEFT(B301,5)="Dres.", LEFT(B301,4)="Prof", LEFT(B301,5)="Prof.", LEFT(B301,3)="PD ", LEFT(B301,7)="Priv.-D" ), LEFT(B301,SEARCH(" ",B301)-1), "" ), "") -> Drs. | D301: =IFERROR( IF(C301="", "", IF(ISNUMBER(SEARCH(".",MID(B301,LEN(C301)+2,3))), MID(B301,LEN(C301)+2,2), "" ) ), "") | E301: =IFERROR( TRIM( IF(C301="", IF(ISNUMBER(SEARCH(",",B301)), LEFT(B301,SEARCH(",",B301)-1), B301), IF(D301="", TRIM(MID(B301, LEN(C301)+2, 999)), TRIM(MID(B301, LEN(C301&" "&D301)+2, 999)) ) ) ), "" ) -> Ohlberg/ Wick | N301: =IF(OR(ISNUMBER(SEARCH("weg",[1]Tabelle1!C301&Customers_0!D301)), ISNUMBER(SEARCH("gekündigt",Customers_0!C301&Customers_0!D301)), ISNUMBER(SEARCH("rente",LOWER(Customers_0!C301&Customers_0!D301)))), "INACTIVE", "ACTIVE") -> ACTIVE | O301: =IF(OR( ISERROR(D301), ISERROR(E301), ISNUMBER(SEARCH("/",E301)), ISNUMBER(SEARCH("-",E301)) ),"PRÜFEN","OK") -> PRÜFEN
A302: =Customers_0!A302 -> 20859 | B302: =IFERROR(MID(Customers_0!B302,1,SEARCH(",",Customers_0!B302)-1),Customers_0!B302) -> R. Majorana | C302: =IFERROR( IF(OR( LEFT(B302,3)="Dr.", LEFT(B302,2)="Dr", LEFT(B302,4)="Dres", LEFT(B302,5)="Dres.", LEFT(B302,4)="Prof", LEFT(B302,5)="Prof.", LEFT(B302,3)="PD ", LEFT(B302,7)="Priv.-D" ), LEFT(B302,SEARCH(" ",B302)-1), "" ), "") | D302: =IFERROR( IF(C302="", "", IF(ISNUMBER(SEARCH(".",MID(B302,LEN(C302)+2,3))), MID(B302,LEN(C302)+2,2), "" ) ), "") | E302: =IFERROR( TRIM( IF(C302="", IF(ISNUMBER(SEARCH(",",B302)), LEFT(B302,SEARCH(",",B302)-1), B302), IF(D302="", TRIM(MID(B302, LEN(C302)+2, 999)), TRIM(MID(B302, LEN(C302&" "&D302)+2, 999)) ) ) ), "" ) -> R. Majorana | N302: =IF(OR(ISNUMBER(SEARCH("weg",[1]Tabelle1!C302&Customers_0!D302)), ISNUMBER(SEARCH("gekündigt",Customers_0!C302&Customers_0!D302)), ISNUMBER(SEARCH("rente",LOWER(Customers_0!C302&Customers_0!D302)))), "INACTIVE", "ACTIVE") -> ACTIVE | O302: =IF(OR( ISERROR(D302), ISERROR(E302), ISNUMBER(SEARCH("/",E302)), ISNUMBER(SEARCH("-",E302)) ),"PRÜFEN","OK") -> OK
A303: =Customers_0!A303 -> 20860 | B303: =IFERROR(MID(Customers_0!B303,1,SEARCH(",",Customers_0!B303)-1),Customers_0!B303) -> Dr. Liebetanz | C303: =IFERROR( IF(OR( LEFT(B303,3)="Dr.", LEFT(B303,2)="Dr", LEFT(B303,4)="Dres", LEFT(B303,5)="Dres.", LEFT(B303,4)="Prof", LEFT(B303,5)="Prof.", LEFT(B303,3)="PD ", LEFT(B303,7)="Priv.-D" ), LEFT(B303,SEARCH(" ",B303)-1), "" ), "") -> Dr. | D303: =IFERROR( IF(C303="", "", IF(ISNUMBER(SEARCH(".",MID(B303,LEN(C303)+2,3))), MID(B303,LEN(C303)+2,2), "" ) ), "") | E303: =IFERROR( TRIM( IF(C303="", IF(ISNUMBER(SEARCH(",",B303)), LEFT(B303,SEARCH(",",B303)-1), B303), IF(D303="", TRIM(MID(B303, LEN(C303)+2, 999)), TRIM(MID(B303, LEN(C303&" "&D303)+2, 999)) ) ) ), "" ) -> Liebetanz | N303: =IF(OR(ISNUMBER(SEARCH("weg",[1]Tabelle1!C303&Customers_0!D303)), ISNUMBER(SEARCH("gekündigt",Customers_0!C303&Customers_0!D303)), ISNUMBER(SEARCH("rente",LOWER(Customers_0!C303&Customers_0!D303)))), "INACTIVE", "ACTIVE") -> ACTIVE | O303: =IF(OR( ISERROR(D303), ISERROR(E303), ISNUMBER(SEARCH("/",E303)), ISNUMBER(SEARCH("-",E303)) ),"PRÜFEN","OK") -> OK
A304: =Customers_0!A304 -> 20861 | B304: =IFERROR(MID(Customers_0!B304,1,SEARCH(",",Customers_0!B304)-1),Customers_0!B304) -> Praxis Günther | C304: =IFERROR( IF(OR( LEFT(B304,3)="Dr.", LEFT(B304,2)="Dr", LEFT(B304,4)="Dres", LEFT(B304,5)="Dres.", LEFT(B304,4)="Prof", LEFT(B304,5)="Prof.", LEFT(B304,3)="PD ", LEFT(B304,7)="Priv.-D" ), LEFT(B304,SEARCH(" ",B304)-1), "" ), "") | D304: =IFERROR( IF(C304="", "", IF(ISNUMBER(SEARCH(".",MID(B304,LEN(C304)+2,3))), MID(B304,LEN(C304)+2,2), "" ) ), "") | E304: =IFERROR( TRIM( IF(C304="", IF(ISNUMBER(SEARCH(",",B304)), LEFT(B304,SEARCH(",",B304)-1), B304), IF(D304="", TRIM(MID(B304, LEN(C304)+2, 999)), TRIM(MID(B304, LEN(C304&" "&D304)+2, 999)) ) ) ), "" ) -> Praxis Günther | N304: =IF(OR(ISNUMBER(SEARCH("weg",[1]Tabelle1!C304&Customers_0!D304)), ISNUMBER(SEARCH("gekündigt",Customers_0!C304&Customers_0!D304)), ISNUMBER(SEARCH("rente",LOWER(Customers_0!C304&Customers_0!D304)))), "INACTIVE", "ACTIVE") -> ACTIVE | O304: =IF(OR( ISERROR(D304), ISERROR(E304), ISNUMBER(SEARCH("/",E304)), ISNUMBER(SEARCH("-",E304)) ),"PRÜFEN","OK") -> OK
A305: =Customers_0!A305 -> 20862 | B305: =IFERROR(MID(Customers_0!B305,1,SEARCH(",",Customers_0!B305)-1),Customers_0!B305) -> Dr. Korth | C305: =IFERROR( IF(OR( LEFT(B305,3)="Dr.", LEFT(B305,2)="Dr", LEFT(B305,4)="Dres", LEFT(B305,5)="Dres.", LEFT(B305,4)="Prof", LEFT(B305,5)="Prof.", LEFT(B305,3)="PD ", LEFT(B305,7)="Priv.-D" ), LEFT(B305,SEARCH(" ",B305)-1), "" ), "") -> Dr. | D305: =IFERROR( IF(C305="", "", IF(ISNUMBER(SEARCH(".",MID(B305,LEN(C305)+2,3))), MID(B305,LEN(C305)+2,2), "" ) ), "") | E305: =IFERROR( TRIM( IF(C305="", IF(ISNUMBER(SEARCH(",",B305)), LEFT(B305,SEARCH(",",B305)-1), B305), IF(D305="", TRIM(MID(B305, LEN(C305)+2, 999)), TRIM(MID(B305, LEN(C305&" "&D305)+2, 999)) ) ) ), "" ) -> Korth | N305: =IF(OR(ISNUMBER(SEARCH("weg",[1]Tabelle1!C305&Customers_0!D305)), ISNUMBER(SEARCH("gekündigt",Customers_0!C305&Customers_0!D305)), ISNUMBER(SEARCH("rente",LOWER(Customers_0!C305&Customers_0!D305)))), "INACTIVE", "ACTIVE") -> ACTIVE | O305: =IF(OR( ISERROR(D305), ISERROR(E305), ISNUMBER(SEARCH("/",E305)), ISNUMBER(SEARCH("-",E305)) ),"PRÜFEN","OK") -> OK
A306: =Customers_0!A306 -> 20863 | B306: =IFERROR(MID(Customers_0!B306,1,SEARCH(",",Customers_0!B306)-1),Customers_0!B306) -> Dr. Wiehn | C306: =IFERROR( IF(OR( LEFT(B306,3)="Dr.", LEFT(B306,2)="Dr", LEFT(B306,4)="Dres", LEFT(B306,5)="Dres.", LEFT(B306,4)="Prof", LEFT(B306,5)="Prof.", LEFT(B306,3)="PD ", LEFT(B306,7)="Priv.-D" ), LEFT(B306,SEARCH(" ",B306)-1), "" ), "") -> Dr. | D306: =IFERROR( IF(C306="", "", IF(ISNUMBER(SEARCH(".",MID(B306,LEN(C306)+2,3))), MID(B306,LEN(C306)+2,2), "" ) ), "") | E306: =IFERROR( TRIM( IF(C306="", IF(ISNUMBER(SEARCH(",",B306)), LEFT(B306,SEARCH(",",B306)-1), B306), IF(D306="", TRIM(MID(B306, LEN(C306)+2, 999)), TRIM(MID(B306, LEN(C306&" "&D306)+2, 999)) ) ) ), "" ) -> Wiehn | N306: =IF(OR(ISNUMBER(SEARCH("weg",[1]Tabelle1!C306&Customers_0!D306)), ISNUMBER(SEARCH("gekündigt",Customers_0!C306&Customers_0!D306)), ISNUMBER(SEARCH("rente",LOWER(Customers_0!C306&Customers_0!D306)))), "INACTIVE", "ACTIVE") -> ACTIVE | O306: =IF(OR( ISERROR(D306), ISERROR(E306), ISNUMBER(SEARCH("/",E306)), ISNUMBER(SEARCH("-",E306)) ),"PRÜFEN","OK") -> OK
... A475: =Customers_0!A475 -> 208091 | B475: =IFERROR(MID(Customers_0!B475,1,SEARCH(",",Customers_0!B475)-1),Customers_0!B475) -> Hebeiß | C475: =IFERROR( IF(OR( LEFT(B475,3)="Dr.", LEFT(B475,2)="Dr", LEFT(B475,4)="Dres", LEFT(B475,5)="Dres.", LEFT(B475,4)="Prof", LEFT(B475,5)="Prof.", LEFT(B475,3)="PD ", LEFT(B475,7)="Priv.-D" ), LEFT(B475,SEARCH(" ",B475)-1), "" ), "") | D475: =IFERROR( IF(C475="", "", IF(ISNUMBER(SEARCH(".",MID(B475,LEN(C475)+2,3))), MID(B475,LEN(C475)+2,2), "" ) ), "") | E475: =IFERROR( TRIM( IF(C475="", IF(ISNUMBER(SEARCH(",",B475)), LEFT(B475,SEARCH(",",B475)-1), B475), IF(D475="", TRIM(MID(B475, LEN(C475)+2, 999)), TRIM(MID(B475, LEN(C475&" "&D475)+2, 999)) ) ) ), "" ) -> Hebeiß | N475: =IF(OR(ISNUMBER(SEARCH("weg",[1]Tabelle1!C475&Customers_0!D475)), ISNUMBER(SEARCH("gekündigt",Customers_0!C475&Customers_0!D475)), ISNUMBER(SEARCH("rente",LOWER(Customers_0!C475&Customers_0!D475)))), "INACTIVE", "ACTIVE") -> ACTIVE | O475: =IF(OR( ISERROR(D475), ISERROR(E475), ISNUMBER(SEARCH("/",E475)), ISNUMBER(SEARCH("-",E475)) ),"PRÜFEN","OK") -> OK
